2025-08-27 23:40:51,757 - matplotlib - DEBUG - matplotlib data path: C:\Users\pablo\AppData\Local\Packages\PythonSoftwareFoundation.Python.3.13_qbz5n2kfra8p0\LocalCache\local-packages\Python313\site-packages\matplotlib\mpl-data
2025-08-27 23:40:51,775 - matplotlib - DEBUG - CONFIGDIR=C:\Users\pablo\.matplotlib
2025-08-27 23:40:51,777 - matplotlib - DEBUG - interactive is False
2025-08-27 23:40:51,778 - matplotlib - DEBUG - platform is win32
2025-08-27 23:40:51,806 - root - INFO - Matplotlib backend configurado correctamente
2025-08-27 23:40:51,861 - root - INFO - CustomTkinter importado correctamente
2025-08-27 23:40:51,901 - root - CRITICAL - No se pudo importar GenealogyApp: cannot import name 'RelacionService' from partially initialized module 'services.relacion_service' (most likely due to a circular import) (c:\Users\pablo\OneDrive\Escritorio\ArbolGenealogico\services\relacion_service.py)
2025-08-27 23:40:51,901 - root - CRITICAL - Verifica la estructura del proyecto:
2025-08-27 23:40:51,902 - root - CRITICAL - Debe tener la siguiente estructura:
2025-08-27 23:40:51,902 - root - CRITICAL - proyecto/
2025-08-27 23:40:52,016 - root - CRITICAL - Error FATAL al importar módulos: cannot import name 'RelacionService' from partially initialized module 'services.relacion_service' (most likely due to a circular import) (c:\Users\pablo\OneDrive\Escritorio\ArbolGenealogico\services\relacion_service.py)
Traceback (most recent call last):
  File "c:\Users\pablo\OneDrive\Escritorio\ArbolGenealogico\main.py", line 35, in <module>
    from gui.app import GenealogyApp
  File "c:\Users\pablo\OneDrive\Escritorio\ArbolGenealogico\gui\app.py", line 14, in <module>
    from services.relacion_service import RelacionService
  File "c:\Users\pablo\OneDrive\Escritorio\ArbolGenealogico\services\relacion_service.py", line 5, in <module>
    from services.simulacion_service import SimulacionService
  File "c:\Users\pablo\OneDrive\Escritorio\ArbolGenealogico\services\simulacion_service.py", line 9, in <module>
    from services.relacion_service import RelacionService
ImportError: cannot import name 'RelacionService' from partially initialized module 'services.relacion_service' (most likely due to a circular import) (c:\Users\pablo\OneDrive\Escritorio\ArbolGenealogico\services\relacion_service.py)
2025-08-28 00:32:56,723 - matplotlib - DEBUG - matplotlib data path: C:\Users\pablo\AppData\Local\Packages\PythonSoftwareFoundation.Python.3.13_qbz5n2kfra8p0\LocalCache\local-packages\Python313\site-packages\matplotlib\mpl-data
2025-08-28 00:32:56,741 - matplotlib - DEBUG - CONFIGDIR=C:\Users\pablo\.matplotlib
2025-08-28 00:32:56,742 - matplotlib - DEBUG - interactive is False
2025-08-28 00:32:56,742 - matplotlib - DEBUG - platform is win32
2025-08-28 00:32:56,768 - root - INFO - Matplotlib backend configurado correctamente
2025-08-28 00:32:56,822 - root - INFO - CustomTkinter importado correctamente
2025-08-28 00:32:56,863 - root - CRITICAL - No se pudo importar GenealogyApp: No module named 'services.utils_service'
2025-08-28 00:32:56,863 - root - CRITICAL - Verifica la estructura del proyecto:
2025-08-28 00:32:56,863 - root - CRITICAL - Debe tener la siguiente estructura:
2025-08-28 00:32:56,864 - root - CRITICAL - proyecto/
2025-08-28 00:32:56,937 - root - CRITICAL - Error FATAL al importar módulos: No module named 'services.utils_service'
Traceback (most recent call last):
  File "c:\Users\pablo\OneDrive\Escritorio\ArbolGenealogico\main.py", line 35, in <module>
    from gui.app import GenealogyApp
  File "c:\Users\pablo\OneDrive\Escritorio\ArbolGenealogico\gui\app.py", line 14, in <module>
    from services.relacion_service import RelacionService
  File "c:\Users\pablo\OneDrive\Escritorio\ArbolGenealogico\services\relacion_service.py", line 5, in <module>
    from services.utils_service import verificar_requisitos_union
ModuleNotFoundError: No module named 'services.utils_service'
2025-08-28 00:33:59,496 - matplotlib - DEBUG - matplotlib data path: C:\Users\pablo\AppData\Local\Packages\PythonSoftwareFoundation.Python.3.13_qbz5n2kfra8p0\LocalCache\local-packages\Python313\site-packages\matplotlib\mpl-data
2025-08-28 00:33:59,511 - matplotlib - DEBUG - CONFIGDIR=C:\Users\pablo\.matplotlib
2025-08-28 00:33:59,512 - matplotlib - DEBUG - interactive is False
2025-08-28 00:33:59,513 - matplotlib - DEBUG - platform is win32
2025-08-28 00:33:59,534 - root - INFO - Matplotlib backend configurado correctamente
2025-08-28 00:33:59,583 - root - INFO - CustomTkinter importado correctamente
2025-08-28 00:33:59,591 - root - CRITICAL - No se pudo importar GenealogyApp: No module named 'services.utils_service'
2025-08-28 00:33:59,591 - root - CRITICAL - Verifica la estructura del proyecto:
2025-08-28 00:33:59,591 - root - CRITICAL - Debe tener la siguiente estructura:
2025-08-28 00:33:59,592 - root - CRITICAL - proyecto/
2025-08-28 00:33:59,663 - root - CRITICAL - Error FATAL al importar módulos: No module named 'services.utils_service'
Traceback (most recent call last):
  File "c:\Users\pablo\OneDrive\Escritorio\ArbolGenealogico\main.py", line 35, in <module>
    from gui.app import GenealogyApp
  File "c:\Users\pablo\OneDrive\Escritorio\ArbolGenealogico\gui\app.py", line 14, in <module>
    from services.relacion_service import RelacionService
  File "c:\Users\pablo\OneDrive\Escritorio\ArbolGenealogico\services\relacion_service.py", line 5, in <module>
    from services.utils_service import verificar_requisitos_union
ModuleNotFoundError: No module named 'services.utils_service'
2025-08-28 00:49:13,413 - matplotlib - DEBUG - matplotlib data path: C:\Users\pablo\AppData\Local\Packages\PythonSoftwareFoundation.Python.3.13_qbz5n2kfra8p0\LocalCache\local-packages\Python313\site-packages\matplotlib\mpl-data
2025-08-28 00:49:13,437 - matplotlib - DEBUG - CONFIGDIR=C:\Users\pablo\.matplotlib
2025-08-28 00:49:13,438 - matplotlib - DEBUG - interactive is False
2025-08-28 00:49:13,439 - matplotlib - DEBUG - platform is win32
2025-08-28 00:49:13,455 - matplotlib - DEBUG - matplotlib data path: C:\Users\pablo\AppData\Local\Packages\PythonSoftwareFoundation.Python.3.13_qbz5n2kfra8p0\LocalCache\local-packages\Python313\site-packages\matplotlib\mpl-data
2025-08-28 00:49:13,463 - root - INFO - Matplotlib backend configurado correctamente
2025-08-28 00:49:13,474 - matplotlib - DEBUG - CONFIGDIR=C:\Users\pablo\.matplotlib
2025-08-28 00:49:13,476 - matplotlib - DEBUG - interactive is False
2025-08-28 00:49:13,477 - matplotlib - DEBUG - platform is win32
2025-08-28 00:49:13,503 - root - INFO - Matplotlib backend configurado correctamente
2025-08-28 00:49:13,519 - root - INFO - CustomTkinter importado correctamente
2025-08-28 00:49:13,553 - root - INFO - CustomTkinter importado correctamente
2025-08-28 00:49:14,009 - matplotlib - DEBUG - CACHEDIR=C:\Users\pablo\.matplotlib
2025-08-28 00:49:14,009 - matplotlib - DEBUG - CACHEDIR=C:\Users\pablo\.matplotlib
2025-08-28 00:49:14,012 - matplotlib.font_manager - DEBUG - Using fontManager instance from C:\Users\pablo\.matplotlib\fontlist-v390.json
2025-08-28 00:49:14,012 - matplotlib.font_manager - DEBUG - Using fontManager instance from C:\Users\pablo\.matplotlib\fontlist-v390.json
2025-08-28 00:49:14,415 - root - INFO - Módulo gui.app importado correctamente
2025-08-28 00:49:14,415 - root - INFO - Módulo gui.app importado correctamente
2025-08-28 00:49:14,416 - root - INFO - Configuración de CustomTkinter establecida
2025-08-28 00:49:14,416 - root - INFO - Configuración de CustomTkinter establecida
2025-08-28 00:49:14,588 - root - INFO - Ventana principal creada
2025-08-28 00:49:14,597 - root - INFO - Ventana principal creada
2025-08-28 00:49:15,518 - root - ERROR - Error inesperado al inicializar GenealogyApp
2025-08-28 00:49:15,519 - root - ERROR - Detalles: No module named 'gui.graph_visualizer'
2025-08-28 00:49:15,521 - root - ERROR - Error inesperado al inicializar GenealogyApp
2025-08-28 00:49:15,521 - root - ERROR - Detalles: No module named 'gui.graph_visualizer'
2025-08-28 00:57:21,072 - matplotlib - DEBUG - matplotlib data path: C:\Users\pablo\AppData\Local\Packages\PythonSoftwareFoundation.Python.3.13_qbz5n2kfra8p0\LocalCache\local-packages\Python313\site-packages\matplotlib\mpl-data
2025-08-28 00:57:21,095 - matplotlib - DEBUG - CONFIGDIR=C:\Users\pablo\.matplotlib
2025-08-28 00:57:21,098 - matplotlib - DEBUG - interactive is False
2025-08-28 00:57:21,099 - matplotlib - DEBUG - platform is win32
2025-08-28 00:57:21,175 - root - INFO - Matplotlib backend configurado correctamente
2025-08-28 00:57:21,259 - root - INFO - CustomTkinter importado correctamente
2025-08-28 00:57:21,443 - matplotlib - DEBUG - CACHEDIR=C:\Users\pablo\.matplotlib
2025-08-28 00:57:21,446 - matplotlib.font_manager - DEBUG - Using fontManager instance from C:\Users\pablo\.matplotlib\fontlist-v390.json
2025-08-28 00:57:21,689 - root - INFO - Módulo gui.app importado correctamente
2025-08-28 00:57:21,690 - root - INFO - Configuración de CustomTkinter establecida
2025-08-28 00:57:21,806 - root - INFO - Ventana principal creada
2025-08-28 00:57:22,349 - root - INFO - GenealogyApp inicializada correctamente
2025-08-28 00:57:22,349 - root - INFO - Iniciando bucle principal de la aplicación...
2025-08-28 01:10:11,757 - root - ERROR - Error en simulación: 'FamilyGraphVisualizer' object has no attribute 'draw_tree'
Traceback (most recent call last):
  File "c:\Users\pablo\OneDrive\Escritorio\ArbolGenealogico\gui\simulation_panel.py", line 141, in run_simulation
    self.draw_tree()
    ~~~~~~~~~~~~~~^^
  File "c:\Users\pablo\OneDrive\Escritorio\ArbolGenealogico\gui\simulation_panel.py", line 227, in draw_tree
    visualizer.draw_tree(self.simulated_family, self.tree_canvas)
    ^^^^^^^^^^^^^^^^^^^^
AttributeError: 'FamilyGraphVisualizer' object has no attribute 'draw_tree'
2025-08-28 01:10:21,713 - root - ERROR - Error en simulación: No module named 'services.utils_service'
Traceback (most recent call last):
  File "c:\Users\pablo\OneDrive\Escritorio\ArbolGenealogico\gui\simulation_panel.py", line 125, in run_simulation
    eventos = SimulacionService.ejecutar_ciclo_completo(
        self.simulated_family,
        self.config
    )
  File "c:\Users\pablo\OneDrive\Escritorio\ArbolGenealogico\services\simulacion_service.py", line 504, in ejecutar_ciclo_completo
    romance_events = SimulacionService.procesar_busqueda_parejas(family, config)
  File "c:\Users\pablo\OneDrive\Escritorio\ArbolGenealogico\services\simulacion_service.py", line 779, in procesar_busqueda_parejas
    success, message = RelacionService.registrar_pareja(family, person.cedula, partner.cedula)
                       ~~~~~~~~~~~~~~~~~~~~~~~~~~~~~~~~^^^^^^^^^^^^^^^^^^^^^^^^^^^^^^^^^^^^^^^
  File "c:\Users\pablo\OneDrive\Escritorio\ArbolGenealogico\services\relacion_service.py", line 101, in registrar_pareja
    from services.utils_service import verificar_requisitos_union
ModuleNotFoundError: No module named 'services.utils_service'
2025-08-28 01:10:21,896 - root - ERROR - Error en simulación: 'FamilyGraphVisualizer' object has no attribute 'draw_tree'
Traceback (most recent call last):
  File "c:\Users\pablo\OneDrive\Escritorio\ArbolGenealogico\gui\simulation_panel.py", line 141, in run_simulation
    self.draw_tree()
    ~~~~~~~~~~~~~~^^
  File "c:\Users\pablo\OneDrive\Escritorio\ArbolGenealogico\gui\simulation_panel.py", line 227, in draw_tree
    visualizer.draw_tree(self.simulated_family, self.tree_canvas)
    ^^^^^^^^^^^^^^^^^^^^
AttributeError: 'FamilyGraphVisualizer' object has no attribute 'draw_tree'
2025-08-28 01:16:11,813 - root - ERROR - Error en simulación: 'FamilyGraphVisualizer' object has no attribute 'draw_tree'
Traceback (most recent call last):
  File "c:\Users\pablo\OneDrive\Escritorio\ArbolGenealogico\gui\simulation_panel.py", line 141, in run_simulation
    self.draw_tree()
    ~~~~~~~~~~~~~~^^
  File "c:\Users\pablo\OneDrive\Escritorio\ArbolGenealogico\gui\simulation_panel.py", line 227, in draw_tree
    visualizer.draw_tree(self.simulated_family, self.tree_canvas)
    ^^^^^^^^^^^^^^^^^^^^
AttributeError: 'FamilyGraphVisualizer' object has no attribute 'draw_tree'
2025-08-28 01:16:21,893 - root - ERROR - Error en simulación: 'FamilyGraphVisualizer' object has no attribute 'draw_tree'
Traceback (most recent call last):
  File "c:\Users\pablo\OneDrive\Escritorio\ArbolGenealogico\gui\simulation_panel.py", line 141, in run_simulation
    self.draw_tree()
    ~~~~~~~~~~~~~~^^
  File "c:\Users\pablo\OneDrive\Escritorio\ArbolGenealogico\gui\simulation_panel.py", line 227, in draw_tree
    visualizer.draw_tree(self.simulated_family, self.tree_canvas)
    ^^^^^^^^^^^^^^^^^^^^
AttributeError: 'FamilyGraphVisualizer' object has no attribute 'draw_tree'
2025-08-28 01:16:31,977 - root - ERROR - Error en simulación: 'FamilyGraphVisualizer' object has no attribute 'draw_tree'
Traceback (most recent call last):
  File "c:\Users\pablo\OneDrive\Escritorio\ArbolGenealogico\gui\simulation_panel.py", line 141, in run_simulation
    self.draw_tree()
    ~~~~~~~~~~~~~~^^
  File "c:\Users\pablo\OneDrive\Escritorio\ArbolGenealogico\gui\simulation_panel.py", line 227, in draw_tree
    visualizer.draw_tree(self.simulated_family, self.tree_canvas)
    ^^^^^^^^^^^^^^^^^^^^
AttributeError: 'FamilyGraphVisualizer' object has no attribute 'draw_tree'
2025-08-28 01:16:42,062 - root - ERROR - Error en simulación: 'FamilyGraphVisualizer' object has no attribute 'draw_tree'
Traceback (most recent call last):
  File "c:\Users\pablo\OneDrive\Escritorio\ArbolGenealogico\gui\simulation_panel.py", line 141, in run_simulation
    self.draw_tree()
    ~~~~~~~~~~~~~~^^
  File "c:\Users\pablo\OneDrive\Escritorio\ArbolGenealogico\gui\simulation_panel.py", line 227, in draw_tree
    visualizer.draw_tree(self.simulated_family, self.tree_canvas)
    ^^^^^^^^^^^^^^^^^^^^
AttributeError: 'FamilyGraphVisualizer' object has no attribute 'draw_tree'
2025-08-28 01:16:52,134 - root - ERROR - Error en simulación: 'FamilyGraphVisualizer' object has no attribute 'draw_tree'
Traceback (most recent call last):
  File "c:\Users\pablo\OneDrive\Escritorio\ArbolGenealogico\gui\simulation_panel.py", line 141, in run_simulation
    self.draw_tree()
    ~~~~~~~~~~~~~~^^
  File "c:\Users\pablo\OneDrive\Escritorio\ArbolGenealogico\gui\simulation_panel.py", line 227, in draw_tree
    visualizer.draw_tree(self.simulated_family, self.tree_canvas)
    ^^^^^^^^^^^^^^^^^^^^
AttributeError: 'FamilyGraphVisualizer' object has no attribute 'draw_tree'
2025-08-28 01:17:02,235 - root - ERROR - Error en simulación: 'FamilyGraphVisualizer' object has no attribute 'draw_tree'
Traceback (most recent call last):
  File "c:\Users\pablo\OneDrive\Escritorio\ArbolGenealogico\gui\simulation_panel.py", line 141, in run_simulation
    self.draw_tree()
    ~~~~~~~~~~~~~~^^
  File "c:\Users\pablo\OneDrive\Escritorio\ArbolGenealogico\gui\simulation_panel.py", line 227, in draw_tree
    visualizer.draw_tree(self.simulated_family, self.tree_canvas)
    ^^^^^^^^^^^^^^^^^^^^
AttributeError: 'FamilyGraphVisualizer' object has no attribute 'draw_tree'
2025-08-28 01:17:12,316 - root - ERROR - Error en simulación: 'FamilyGraphVisualizer' object has no attribute 'draw_tree'
Traceback (most recent call last):
  File "c:\Users\pablo\OneDrive\Escritorio\ArbolGenealogico\gui\simulation_panel.py", line 141, in run_simulation
    self.draw_tree()
    ~~~~~~~~~~~~~~^^
  File "c:\Users\pablo\OneDrive\Escritorio\ArbolGenealogico\gui\simulation_panel.py", line 227, in draw_tree
    visualizer.draw_tree(self.simulated_family, self.tree_canvas)
    ^^^^^^^^^^^^^^^^^^^^
AttributeError: 'FamilyGraphVisualizer' object has no attribute 'draw_tree'
2025-08-28 01:17:22,411 - root - ERROR - Error en simulación: 'FamilyGraphVisualizer' object has no attribute 'draw_tree'
Traceback (most recent call last):
  File "c:\Users\pablo\OneDrive\Escritorio\ArbolGenealogico\gui\simulation_panel.py", line 141, in run_simulation
    self.draw_tree()
    ~~~~~~~~~~~~~~^^
  File "c:\Users\pablo\OneDrive\Escritorio\ArbolGenealogico\gui\simulation_panel.py", line 227, in draw_tree
    visualizer.draw_tree(self.simulated_family, self.tree_canvas)
    ^^^^^^^^^^^^^^^^^^^^
AttributeError: 'FamilyGraphVisualizer' object has no attribute 'draw_tree'
2025-08-28 01:17:32,462 - root - ERROR - Error en simulación: No module named 'services.utils_service'
Traceback (most recent call last):
  File "c:\Users\pablo\OneDrive\Escritorio\ArbolGenealogico\gui\simulation_panel.py", line 125, in run_simulation
    eventos = SimulacionService.ejecutar_ciclo_completo(
        self.simulated_family,
        self.config
    )
  File "c:\Users\pablo\OneDrive\Escritorio\ArbolGenealogico\services\simulacion_service.py", line 504, in ejecutar_ciclo_completo
    romance_events = SimulacionService.procesar_busqueda_parejas(family, config)
  File "c:\Users\pablo\OneDrive\Escritorio\ArbolGenealogico\services\simulacion_service.py", line 779, in procesar_busqueda_parejas
    success, message = RelacionService.registrar_pareja(family, person.cedula, partner.cedula)
                       ~~~~~~~~~~~~~~~~~~~~~~~~~~~~~~~~^^^^^^^^^^^^^^^^^^^^^^^^^^^^^^^^^^^^^^^
  File "c:\Users\pablo\OneDrive\Escritorio\ArbolGenealogico\services\relacion_service.py", line 101, in registrar_pareja
    from services.utils_service import verificar_requisitos_union
ModuleNotFoundError: No module named 'services.utils_service'
2025-08-28 01:17:32,601 - root - ERROR - Error en simulación: 'FamilyGraphVisualizer' object has no attribute 'draw_tree'
Traceback (most recent call last):
  File "c:\Users\pablo\OneDrive\Escritorio\ArbolGenealogico\gui\simulation_panel.py", line 141, in run_simulation
    self.draw_tree()
    ~~~~~~~~~~~~~~^^
  File "c:\Users\pablo\OneDrive\Escritorio\ArbolGenealogico\gui\simulation_panel.py", line 227, in draw_tree
    visualizer.draw_tree(self.simulated_family, self.tree_canvas)
    ^^^^^^^^^^^^^^^^^^^^
AttributeError: 'FamilyGraphVisualizer' object has no attribute 'draw_tree'
2025-08-28 01:17:42,677 - root - ERROR - Error en simulación: 'FamilyGraphVisualizer' object has no attribute 'draw_tree'
Traceback (most recent call last):
  File "c:\Users\pablo\OneDrive\Escritorio\ArbolGenealogico\gui\simulation_panel.py", line 141, in run_simulation
    self.draw_tree()
    ~~~~~~~~~~~~~~^^
  File "c:\Users\pablo\OneDrive\Escritorio\ArbolGenealogico\gui\simulation_panel.py", line 227, in draw_tree
    visualizer.draw_tree(self.simulated_family, self.tree_canvas)
    ^^^^^^^^^^^^^^^^^^^^
AttributeError: 'FamilyGraphVisualizer' object has no attribute 'draw_tree'
2025-08-28 01:17:52,775 - root - ERROR - Error en simulación: 'FamilyGraphVisualizer' object has no attribute 'draw_tree'
Traceback (most recent call last):
  File "c:\Users\pablo\OneDrive\Escritorio\ArbolGenealogico\gui\simulation_panel.py", line 141, in run_simulation
    self.draw_tree()
    ~~~~~~~~~~~~~~^^
  File "c:\Users\pablo\OneDrive\Escritorio\ArbolGenealogico\gui\simulation_panel.py", line 227, in draw_tree
    visualizer.draw_tree(self.simulated_family, self.tree_canvas)
    ^^^^^^^^^^^^^^^^^^^^
AttributeError: 'FamilyGraphVisualizer' object has no attribute 'draw_tree'
2025-08-28 01:18:02,864 - root - ERROR - Error en simulación: 'FamilyGraphVisualizer' object has no attribute 'draw_tree'
Traceback (most recent call last):
  File "c:\Users\pablo\OneDrive\Escritorio\ArbolGenealogico\gui\simulation_panel.py", line 141, in run_simulation
    self.draw_tree()
    ~~~~~~~~~~~~~~^^
  File "c:\Users\pablo\OneDrive\Escritorio\ArbolGenealogico\gui\simulation_panel.py", line 227, in draw_tree
    visualizer.draw_tree(self.simulated_family, self.tree_canvas)
    ^^^^^^^^^^^^^^^^^^^^
AttributeError: 'FamilyGraphVisualizer' object has no attribute 'draw_tree'
2025-08-28 01:18:12,952 - root - ERROR - Error en simulación: 'FamilyGraphVisualizer' object has no attribute 'draw_tree'
Traceback (most recent call last):
  File "c:\Users\pablo\OneDrive\Escritorio\ArbolGenealogico\gui\simulation_panel.py", line 141, in run_simulation
    self.draw_tree()
    ~~~~~~~~~~~~~~^^
  File "c:\Users\pablo\OneDrive\Escritorio\ArbolGenealogico\gui\simulation_panel.py", line 227, in draw_tree
    visualizer.draw_tree(self.simulated_family, self.tree_canvas)
    ^^^^^^^^^^^^^^^^^^^^
AttributeError: 'FamilyGraphVisualizer' object has no attribute 'draw_tree'
2025-08-28 01:18:23,039 - root - ERROR - Error en simulación: 'FamilyGraphVisualizer' object has no attribute 'draw_tree'
Traceback (most recent call last):
  File "c:\Users\pablo\OneDrive\Escritorio\ArbolGenealogico\gui\simulation_panel.py", line 141, in run_simulation
    self.draw_tree()
    ~~~~~~~~~~~~~~^^
  File "c:\Users\pablo\OneDrive\Escritorio\ArbolGenealogico\gui\simulation_panel.py", line 227, in draw_tree
    visualizer.draw_tree(self.simulated_family, self.tree_canvas)
    ^^^^^^^^^^^^^^^^^^^^
AttributeError: 'FamilyGraphVisualizer' object has no attribute 'draw_tree'
2025-08-28 01:18:33,092 - root - ERROR - Error en simulación: No module named 'services.utils_service'
Traceback (most recent call last):
  File "c:\Users\pablo\OneDrive\Escritorio\ArbolGenealogico\gui\simulation_panel.py", line 125, in run_simulation
    eventos = SimulacionService.ejecutar_ciclo_completo(
        self.simulated_family,
        self.config
    )
  File "c:\Users\pablo\OneDrive\Escritorio\ArbolGenealogico\services\simulacion_service.py", line 504, in ejecutar_ciclo_completo
    romance_events = SimulacionService.procesar_busqueda_parejas(family, config)
  File "c:\Users\pablo\OneDrive\Escritorio\ArbolGenealogico\services\simulacion_service.py", line 779, in procesar_busqueda_parejas
    success, message = RelacionService.registrar_pareja(family, person.cedula, partner.cedula)
                       ~~~~~~~~~~~~~~~~~~~~~~~~~~~~~~~~^^^^^^^^^^^^^^^^^^^^^^^^^^^^^^^^^^^^^^^
  File "c:\Users\pablo\OneDrive\Escritorio\ArbolGenealogico\services\relacion_service.py", line 101, in registrar_pareja
    from services.utils_service import verificar_requisitos_union
ModuleNotFoundError: No module named 'services.utils_service'
2025-08-28 01:18:33,236 - root - ERROR - Error en simulación: 'FamilyGraphVisualizer' object has no attribute 'draw_tree'
Traceback (most recent call last):
  File "c:\Users\pablo\OneDrive\Escritorio\ArbolGenealogico\gui\simulation_panel.py", line 141, in run_simulation
    self.draw_tree()
    ~~~~~~~~~~~~~~^^
  File "c:\Users\pablo\OneDrive\Escritorio\ArbolGenealogico\gui\simulation_panel.py", line 227, in draw_tree
    visualizer.draw_tree(self.simulated_family, self.tree_canvas)
    ^^^^^^^^^^^^^^^^^^^^
AttributeError: 'FamilyGraphVisualizer' object has no attribute 'draw_tree'
2025-08-28 01:18:43,321 - root - ERROR - Error en simulación: 'FamilyGraphVisualizer' object has no attribute 'draw_tree'
Traceback (most recent call last):
  File "c:\Users\pablo\OneDrive\Escritorio\ArbolGenealogico\gui\simulation_panel.py", line 141, in run_simulation
    self.draw_tree()
    ~~~~~~~~~~~~~~^^
  File "c:\Users\pablo\OneDrive\Escritorio\ArbolGenealogico\gui\simulation_panel.py", line 227, in draw_tree
    visualizer.draw_tree(self.simulated_family, self.tree_canvas)
    ^^^^^^^^^^^^^^^^^^^^
AttributeError: 'FamilyGraphVisualizer' object has no attribute 'draw_tree'
2025-08-28 01:18:53,414 - root - ERROR - Error en simulación: 'FamilyGraphVisualizer' object has no attribute 'draw_tree'
Traceback (most recent call last):
  File "c:\Users\pablo\OneDrive\Escritorio\ArbolGenealogico\gui\simulation_panel.py", line 141, in run_simulation
    self.draw_tree()
    ~~~~~~~~~~~~~~^^
  File "c:\Users\pablo\OneDrive\Escritorio\ArbolGenealogico\gui\simulation_panel.py", line 227, in draw_tree
    visualizer.draw_tree(self.simulated_family, self.tree_canvas)
    ^^^^^^^^^^^^^^^^^^^^
AttributeError: 'FamilyGraphVisualizer' object has no attribute 'draw_tree'
2025-08-28 01:19:03,464 - root - ERROR - Error en simulación: No module named 'services.utils_service'
Traceback (most recent call last):
  File "c:\Users\pablo\OneDrive\Escritorio\ArbolGenealogico\gui\simulation_panel.py", line 125, in run_simulation
    eventos = SimulacionService.ejecutar_ciclo_completo(
        self.simulated_family,
        self.config
    )
  File "c:\Users\pablo\OneDrive\Escritorio\ArbolGenealogico\services\simulacion_service.py", line 504, in ejecutar_ciclo_completo
    romance_events = SimulacionService.procesar_busqueda_parejas(family, config)
  File "c:\Users\pablo\OneDrive\Escritorio\ArbolGenealogico\services\simulacion_service.py", line 779, in procesar_busqueda_parejas
    success, message = RelacionService.registrar_pareja(family, person.cedula, partner.cedula)
                       ~~~~~~~~~~~~~~~~~~~~~~~~~~~~~~~~^^^^^^^^^^^^^^^^^^^^^^^^^^^^^^^^^^^^^^^
  File "c:\Users\pablo\OneDrive\Escritorio\ArbolGenealogico\services\relacion_service.py", line 101, in registrar_pareja
    from services.utils_service import verificar_requisitos_union
ModuleNotFoundError: No module named 'services.utils_service'
2025-08-28 01:19:03,610 - root - ERROR - Error en simulación: 'FamilyGraphVisualizer' object has no attribute 'draw_tree'
Traceback (most recent call last):
  File "c:\Users\pablo\OneDrive\Escritorio\ArbolGenealogico\gui\simulation_panel.py", line 141, in run_simulation
    self.draw_tree()
    ~~~~~~~~~~~~~~^^
  File "c:\Users\pablo\OneDrive\Escritorio\ArbolGenealogico\gui\simulation_panel.py", line 227, in draw_tree
    visualizer.draw_tree(self.simulated_family, self.tree_canvas)
    ^^^^^^^^^^^^^^^^^^^^
AttributeError: 'FamilyGraphVisualizer' object has no attribute 'draw_tree'
2025-08-28 01:19:13,659 - root - ERROR - Error en simulación: No module named 'services.utils_service'
Traceback (most recent call last):
  File "c:\Users\pablo\OneDrive\Escritorio\ArbolGenealogico\gui\simulation_panel.py", line 125, in run_simulation
    eventos = SimulacionService.ejecutar_ciclo_completo(
        self.simulated_family,
        self.config
    )
  File "c:\Users\pablo\OneDrive\Escritorio\ArbolGenealogico\services\simulacion_service.py", line 504, in ejecutar_ciclo_completo
    romance_events = SimulacionService.procesar_busqueda_parejas(family, config)
  File "c:\Users\pablo\OneDrive\Escritorio\ArbolGenealogico\services\simulacion_service.py", line 779, in procesar_busqueda_parejas
    success, message = RelacionService.registrar_pareja(family, person.cedula, partner.cedula)
                       ~~~~~~~~~~~~~~~~~~~~~~~~~~~~~~~~^^^^^^^^^^^^^^^^^^^^^^^^^^^^^^^^^^^^^^^
  File "c:\Users\pablo\OneDrive\Escritorio\ArbolGenealogico\services\relacion_service.py", line 101, in registrar_pareja
    from services.utils_service import verificar_requisitos_union
ModuleNotFoundError: No module named 'services.utils_service'
2025-08-28 01:19:13,803 - root - ERROR - Error en simulación: 'FamilyGraphVisualizer' object has no attribute 'draw_tree'
Traceback (most recent call last):
  File "c:\Users\pablo\OneDrive\Escritorio\ArbolGenealogico\gui\simulation_panel.py", line 141, in run_simulation
    self.draw_tree()
    ~~~~~~~~~~~~~~^^
  File "c:\Users\pablo\OneDrive\Escritorio\ArbolGenealogico\gui\simulation_panel.py", line 227, in draw_tree
    visualizer.draw_tree(self.simulated_family, self.tree_canvas)
    ^^^^^^^^^^^^^^^^^^^^
AttributeError: 'FamilyGraphVisualizer' object has no attribute 'draw_tree'
2025-08-28 01:19:23,891 - root - ERROR - Error en simulación: 'FamilyGraphVisualizer' object has no attribute 'draw_tree'
Traceback (most recent call last):
  File "c:\Users\pablo\OneDrive\Escritorio\ArbolGenealogico\gui\simulation_panel.py", line 141, in run_simulation
    self.draw_tree()
    ~~~~~~~~~~~~~~^^
  File "c:\Users\pablo\OneDrive\Escritorio\ArbolGenealogico\gui\simulation_panel.py", line 227, in draw_tree
    visualizer.draw_tree(self.simulated_family, self.tree_canvas)
    ^^^^^^^^^^^^^^^^^^^^
AttributeError: 'FamilyGraphVisualizer' object has no attribute 'draw_tree'
2025-08-28 01:19:33,970 - root - ERROR - Error en simulación: 'FamilyGraphVisualizer' object has no attribute 'draw_tree'
Traceback (most recent call last):
  File "c:\Users\pablo\OneDrive\Escritorio\ArbolGenealogico\gui\simulation_panel.py", line 141, in run_simulation
    self.draw_tree()
    ~~~~~~~~~~~~~~^^
  File "c:\Users\pablo\OneDrive\Escritorio\ArbolGenealogico\gui\simulation_panel.py", line 227, in draw_tree
    visualizer.draw_tree(self.simulated_family, self.tree_canvas)
    ^^^^^^^^^^^^^^^^^^^^
AttributeError: 'FamilyGraphVisualizer' object has no attribute 'draw_tree'
2025-08-28 01:19:44,060 - root - ERROR - Error en simulación: 'FamilyGraphVisualizer' object has no attribute 'draw_tree'
Traceback (most recent call last):
  File "c:\Users\pablo\OneDrive\Escritorio\ArbolGenealogico\gui\simulation_panel.py", line 141, in run_simulation
    self.draw_tree()
    ~~~~~~~~~~~~~~^^
  File "c:\Users\pablo\OneDrive\Escritorio\ArbolGenealogico\gui\simulation_panel.py", line 227, in draw_tree
    visualizer.draw_tree(self.simulated_family, self.tree_canvas)
    ^^^^^^^^^^^^^^^^^^^^
AttributeError: 'FamilyGraphVisualizer' object has no attribute 'draw_tree'
2025-08-28 01:19:54,153 - root - ERROR - Error en simulación: 'FamilyGraphVisualizer' object has no attribute 'draw_tree'
Traceback (most recent call last):
  File "c:\Users\pablo\OneDrive\Escritorio\ArbolGenealogico\gui\simulation_panel.py", line 141, in run_simulation
    self.draw_tree()
    ~~~~~~~~~~~~~~^^
  File "c:\Users\pablo\OneDrive\Escritorio\ArbolGenealogico\gui\simulation_panel.py", line 227, in draw_tree
    visualizer.draw_tree(self.simulated_family, self.tree_canvas)
    ^^^^^^^^^^^^^^^^^^^^
AttributeError: 'FamilyGraphVisualizer' object has no attribute 'draw_tree'
2025-08-28 01:20:04,236 - root - ERROR - Error en simulación: 'FamilyGraphVisualizer' object has no attribute 'draw_tree'
Traceback (most recent call last):
  File "c:\Users\pablo\OneDrive\Escritorio\ArbolGenealogico\gui\simulation_panel.py", line 141, in run_simulation
    self.draw_tree()
    ~~~~~~~~~~~~~~^^
  File "c:\Users\pablo\OneDrive\Escritorio\ArbolGenealogico\gui\simulation_panel.py", line 227, in draw_tree
    visualizer.draw_tree(self.simulated_family, self.tree_canvas)
    ^^^^^^^^^^^^^^^^^^^^
AttributeError: 'FamilyGraphVisualizer' object has no attribute 'draw_tree'
2025-08-28 01:20:14,316 - root - ERROR - Error en simulación: 'FamilyGraphVisualizer' object has no attribute 'draw_tree'
Traceback (most recent call last):
  File "c:\Users\pablo\OneDrive\Escritorio\ArbolGenealogico\gui\simulation_panel.py", line 141, in run_simulation
    self.draw_tree()
    ~~~~~~~~~~~~~~^^
  File "c:\Users\pablo\OneDrive\Escritorio\ArbolGenealogico\gui\simulation_panel.py", line 227, in draw_tree
    visualizer.draw_tree(self.simulated_family, self.tree_canvas)
    ^^^^^^^^^^^^^^^^^^^^
AttributeError: 'FamilyGraphVisualizer' object has no attribute 'draw_tree'
2025-08-28 01:20:24,394 - root - ERROR - Error en simulación: 'FamilyGraphVisualizer' object has no attribute 'draw_tree'
Traceback (most recent call last):
  File "c:\Users\pablo\OneDrive\Escritorio\ArbolGenealogico\gui\simulation_panel.py", line 141, in run_simulation
    self.draw_tree()
    ~~~~~~~~~~~~~~^^
  File "c:\Users\pablo\OneDrive\Escritorio\ArbolGenealogico\gui\simulation_panel.py", line 227, in draw_tree
    visualizer.draw_tree(self.simulated_family, self.tree_canvas)
    ^^^^^^^^^^^^^^^^^^^^
AttributeError: 'FamilyGraphVisualizer' object has no attribute 'draw_tree'
2025-08-28 01:20:34,460 - root - ERROR - Error en simulación: 'FamilyGraphVisualizer' object has no attribute 'draw_tree'
Traceback (most recent call last):
  File "c:\Users\pablo\OneDrive\Escritorio\ArbolGenealogico\gui\simulation_panel.py", line 141, in run_simulation
    self.draw_tree()
    ~~~~~~~~~~~~~~^^
  File "c:\Users\pablo\OneDrive\Escritorio\ArbolGenealogico\gui\simulation_panel.py", line 227, in draw_tree
    visualizer.draw_tree(self.simulated_family, self.tree_canvas)
    ^^^^^^^^^^^^^^^^^^^^
AttributeError: 'FamilyGraphVisualizer' object has no attribute 'draw_tree'
2025-08-28 01:20:44,534 - root - ERROR - Error en simulación: 'FamilyGraphVisualizer' object has no attribute 'draw_tree'
Traceback (most recent call last):
  File "c:\Users\pablo\OneDrive\Escritorio\ArbolGenealogico\gui\simulation_panel.py", line 141, in run_simulation
    self.draw_tree()
    ~~~~~~~~~~~~~~^^
  File "c:\Users\pablo\OneDrive\Escritorio\ArbolGenealogico\gui\simulation_panel.py", line 227, in draw_tree
    visualizer.draw_tree(self.simulated_family, self.tree_canvas)
    ^^^^^^^^^^^^^^^^^^^^
AttributeError: 'FamilyGraphVisualizer' object has no attribute 'draw_tree'
2025-08-28 01:20:54,608 - root - ERROR - Error en simulación: 'FamilyGraphVisualizer' object has no attribute 'draw_tree'
Traceback (most recent call last):
  File "c:\Users\pablo\OneDrive\Escritorio\ArbolGenealogico\gui\simulation_panel.py", line 141, in run_simulation
    self.draw_tree()
    ~~~~~~~~~~~~~~^^
  File "c:\Users\pablo\OneDrive\Escritorio\ArbolGenealogico\gui\simulation_panel.py", line 227, in draw_tree
    visualizer.draw_tree(self.simulated_family, self.tree_canvas)
    ^^^^^^^^^^^^^^^^^^^^
AttributeError: 'FamilyGraphVisualizer' object has no attribute 'draw_tree'
2025-08-28 01:21:04,676 - root - ERROR - Error en simulación: 'FamilyGraphVisualizer' object has no attribute 'draw_tree'
Traceback (most recent call last):
  File "c:\Users\pablo\OneDrive\Escritorio\ArbolGenealogico\gui\simulation_panel.py", line 141, in run_simulation
    self.draw_tree()
    ~~~~~~~~~~~~~~^^
  File "c:\Users\pablo\OneDrive\Escritorio\ArbolGenealogico\gui\simulation_panel.py", line 227, in draw_tree
    visualizer.draw_tree(self.simulated_family, self.tree_canvas)
    ^^^^^^^^^^^^^^^^^^^^
AttributeError: 'FamilyGraphVisualizer' object has no attribute 'draw_tree'
2025-08-28 01:21:14,760 - root - ERROR - Error en simulación: 'FamilyGraphVisualizer' object has no attribute 'draw_tree'
Traceback (most recent call last):
  File "c:\Users\pablo\OneDrive\Escritorio\ArbolGenealogico\gui\simulation_panel.py", line 141, in run_simulation
    self.draw_tree()
    ~~~~~~~~~~~~~~^^
  File "c:\Users\pablo\OneDrive\Escritorio\ArbolGenealogico\gui\simulation_panel.py", line 227, in draw_tree
    visualizer.draw_tree(self.simulated_family, self.tree_canvas)
    ^^^^^^^^^^^^^^^^^^^^
AttributeError: 'FamilyGraphVisualizer' object has no attribute 'draw_tree'
2025-08-28 01:21:24,839 - root - ERROR - Error en simulación: 'FamilyGraphVisualizer' object has no attribute 'draw_tree'
Traceback (most recent call last):
  File "c:\Users\pablo\OneDrive\Escritorio\ArbolGenealogico\gui\simulation_panel.py", line 141, in run_simulation
    self.draw_tree()
    ~~~~~~~~~~~~~~^^
  File "c:\Users\pablo\OneDrive\Escritorio\ArbolGenealogico\gui\simulation_panel.py", line 227, in draw_tree
    visualizer.draw_tree(self.simulated_family, self.tree_canvas)
    ^^^^^^^^^^^^^^^^^^^^
AttributeError: 'FamilyGraphVisualizer' object has no attribute 'draw_tree'
2025-08-28 01:21:34,909 - root - ERROR - Error en simulación: 'FamilyGraphVisualizer' object has no attribute 'draw_tree'
Traceback (most recent call last):
  File "c:\Users\pablo\OneDrive\Escritorio\ArbolGenealogico\gui\simulation_panel.py", line 141, in run_simulation
    self.draw_tree()
    ~~~~~~~~~~~~~~^^
  File "c:\Users\pablo\OneDrive\Escritorio\ArbolGenealogico\gui\simulation_panel.py", line 227, in draw_tree
    visualizer.draw_tree(self.simulated_family, self.tree_canvas)
    ^^^^^^^^^^^^^^^^^^^^
AttributeError: 'FamilyGraphVisualizer' object has no attribute 'draw_tree'
2025-08-28 01:21:44,979 - root - ERROR - Error en simulación: 'FamilyGraphVisualizer' object has no attribute 'draw_tree'
Traceback (most recent call last):
  File "c:\Users\pablo\OneDrive\Escritorio\ArbolGenealogico\gui\simulation_panel.py", line 141, in run_simulation
    self.draw_tree()
    ~~~~~~~~~~~~~~^^
  File "c:\Users\pablo\OneDrive\Escritorio\ArbolGenealogico\gui\simulation_panel.py", line 227, in draw_tree
    visualizer.draw_tree(self.simulated_family, self.tree_canvas)
    ^^^^^^^^^^^^^^^^^^^^
AttributeError: 'FamilyGraphVisualizer' object has no attribute 'draw_tree'
2025-08-28 01:21:55,046 - root - ERROR - Error en simulación: 'FamilyGraphVisualizer' object has no attribute 'draw_tree'
Traceback (most recent call last):
  File "c:\Users\pablo\OneDrive\Escritorio\ArbolGenealogico\gui\simulation_panel.py", line 141, in run_simulation
    self.draw_tree()
    ~~~~~~~~~~~~~~^^
  File "c:\Users\pablo\OneDrive\Escritorio\ArbolGenealogico\gui\simulation_panel.py", line 227, in draw_tree
    visualizer.draw_tree(self.simulated_family, self.tree_canvas)
    ^^^^^^^^^^^^^^^^^^^^
AttributeError: 'FamilyGraphVisualizer' object has no attribute 'draw_tree'
2025-08-28 01:22:05,105 - root - ERROR - Error en simulación: 'FamilyGraphVisualizer' object has no attribute 'draw_tree'
Traceback (most recent call last):
  File "c:\Users\pablo\OneDrive\Escritorio\ArbolGenealogico\gui\simulation_panel.py", line 141, in run_simulation
    self.draw_tree()
    ~~~~~~~~~~~~~~^^
  File "c:\Users\pablo\OneDrive\Escritorio\ArbolGenealogico\gui\simulation_panel.py", line 227, in draw_tree
    visualizer.draw_tree(self.simulated_family, self.tree_canvas)
    ^^^^^^^^^^^^^^^^^^^^
AttributeError: 'FamilyGraphVisualizer' object has no attribute 'draw_tree'
2025-08-28 01:22:15,171 - root - ERROR - Error en simulación: 'FamilyGraphVisualizer' object has no attribute 'draw_tree'
Traceback (most recent call last):
  File "c:\Users\pablo\OneDrive\Escritorio\ArbolGenealogico\gui\simulation_panel.py", line 141, in run_simulation
    self.draw_tree()
    ~~~~~~~~~~~~~~^^
  File "c:\Users\pablo\OneDrive\Escritorio\ArbolGenealogico\gui\simulation_panel.py", line 227, in draw_tree
    visualizer.draw_tree(self.simulated_family, self.tree_canvas)
    ^^^^^^^^^^^^^^^^^^^^
AttributeError: 'FamilyGraphVisualizer' object has no attribute 'draw_tree'
2025-08-28 01:22:25,236 - root - ERROR - Error en simulación: 'FamilyGraphVisualizer' object has no attribute 'draw_tree'
Traceback (most recent call last):
  File "c:\Users\pablo\OneDrive\Escritorio\ArbolGenealogico\gui\simulation_panel.py", line 141, in run_simulation
    self.draw_tree()
    ~~~~~~~~~~~~~~^^
  File "c:\Users\pablo\OneDrive\Escritorio\ArbolGenealogico\gui\simulation_panel.py", line 227, in draw_tree
    visualizer.draw_tree(self.simulated_family, self.tree_canvas)
    ^^^^^^^^^^^^^^^^^^^^
AttributeError: 'FamilyGraphVisualizer' object has no attribute 'draw_tree'
2025-08-28 01:22:35,303 - root - ERROR - Error en simulación: 'FamilyGraphVisualizer' object has no attribute 'draw_tree'
Traceback (most recent call last):
  File "c:\Users\pablo\OneDrive\Escritorio\ArbolGenealogico\gui\simulation_panel.py", line 141, in run_simulation
    self.draw_tree()
    ~~~~~~~~~~~~~~^^
  File "c:\Users\pablo\OneDrive\Escritorio\ArbolGenealogico\gui\simulation_panel.py", line 227, in draw_tree
    visualizer.draw_tree(self.simulated_family, self.tree_canvas)
    ^^^^^^^^^^^^^^^^^^^^
AttributeError: 'FamilyGraphVisualizer' object has no attribute 'draw_tree'
2025-08-28 01:22:45,368 - root - ERROR - Error en simulación: 'FamilyGraphVisualizer' object has no attribute 'draw_tree'
Traceback (most recent call last):
  File "c:\Users\pablo\OneDrive\Escritorio\ArbolGenealogico\gui\simulation_panel.py", line 141, in run_simulation
    self.draw_tree()
    ~~~~~~~~~~~~~~^^
  File "c:\Users\pablo\OneDrive\Escritorio\ArbolGenealogico\gui\simulation_panel.py", line 227, in draw_tree
    visualizer.draw_tree(self.simulated_family, self.tree_canvas)
    ^^^^^^^^^^^^^^^^^^^^
AttributeError: 'FamilyGraphVisualizer' object has no attribute 'draw_tree'
2025-08-28 14:14:12,922 - matplotlib - DEBUG - matplotlib data path: C:\Users\USER\AppData\Local\Packages\PythonSoftwareFoundation.Python.3.11_qbz5n2kfra8p0\LocalCache\local-packages\Python311\site-packages\matplotlib\mpl-data
2025-08-28 14:14:12,977 - matplotlib - DEBUG - CONFIGDIR=C:\Users\USER\.matplotlib
2025-08-28 14:14:12,979 - matplotlib - DEBUG - interactive is False
2025-08-28 14:14:12,980 - matplotlib - DEBUG - platform is win32
2025-08-28 14:14:13,156 - root - INFO - Matplotlib backend configurado correctamente
2025-08-28 14:14:13,955 - root - INFO - CustomTkinter importado correctamente
2025-08-28 14:14:17,501 - matplotlib - DEBUG - CACHEDIR=C:\Users\USER\.matplotlib
2025-08-28 14:14:17,511 - matplotlib.font_manager - DEBUG - Using fontManager instance from C:\Users\USER\.matplotlib\fontlist-v390.json
2025-08-28 14:14:19,333 - root - INFO - Módulo gui.app importado correctamente
2025-08-28 14:14:19,334 - root - INFO - Configuración de CustomTkinter establecida
2025-08-28 14:14:19,923 - root - INFO - Ventana principal creada
2025-08-28 14:14:21,335 - root - INFO - GenealogyApp inicializada correctamente
2025-08-28 14:14:21,335 - root - INFO - Iniciando bucle principal de la aplicación...
2025-08-28 14:18:58,027 - matplotlib - DEBUG - matplotlib data path: C:\Users\USER\AppData\Local\Packages\PythonSoftwareFoundation.Python.3.11_qbz5n2kfra8p0\LocalCache\local-packages\Python311\site-packages\matplotlib\mpl-data
2025-08-28 14:18:58,051 - matplotlib - DEBUG - CONFIGDIR=C:\Users\USER\.matplotlib
2025-08-28 14:18:58,055 - matplotlib - DEBUG - interactive is False
2025-08-28 14:18:58,055 - matplotlib - DEBUG - platform is win32
2025-08-28 14:18:58,081 - root - INFO - Matplotlib backend configurado correctamente
2025-08-28 14:18:58,159 - root - INFO - CustomTkinter importado correctamente
2025-08-28 14:18:58,275 - root - CRITICAL - Error FATAL al importar módulos: invalid syntax (relacion_service.py, line 5)
Traceback (most recent call last):
  File "c:\Users\USER\OneDrive\Escritorio\ArbolGenealogico\main.py", line 35, in <module>
    from gui.app import GenealogyApp
  File "c:\Users\USER\OneDrive\Escritorio\ArbolGenealogico\gui\app.py", line 14, in <module>
    from services.relacion_service import RelacionService
  File "c:\Users\USER\OneDrive\Escritorio\ArbolGenealogico\services\relacion_service.py", line 5
    from utils.utils service import verificar_requisitos_union
                     ^^^^^^^
SyntaxError: invalid syntax
2025-08-28 14:36:03,160 - matplotlib - DEBUG - matplotlib data path: C:\Users\USER\AppData\Local\Packages\PythonSoftwareFoundation.Python.3.11_qbz5n2kfra8p0\LocalCache\local-packages\Python311\site-packages\matplotlib\mpl-data
2025-08-28 14:36:03,181 - matplotlib - DEBUG - CONFIGDIR=C:\Users\USER\.matplotlib
2025-08-28 14:36:03,184 - matplotlib - DEBUG - interactive is False
2025-08-28 14:36:03,185 - matplotlib - DEBUG - platform is win32
2025-08-28 14:36:03,205 - root - INFO - Matplotlib backend configurado correctamente
2025-08-28 14:36:03,262 - root - INFO - CustomTkinter importado correctamente
2025-08-28 14:36:03,548 - matplotlib - DEBUG - CACHEDIR=C:\Users\USER\.matplotlib
2025-08-28 14:36:03,552 - matplotlib.font_manager - DEBUG - Using fontManager instance from C:\Users\USER\.matplotlib\fontlist-v390.json
2025-08-28 14:36:03,859 - root - INFO - Módulo gui.app importado correctamente
2025-08-28 14:36:03,860 - root - INFO - Configuración de CustomTkinter establecida
2025-08-28 14:36:03,932 - root - INFO - Ventana principal creada
2025-08-28 14:36:04,395 - root - INFO - GenealogyApp inicializada correctamente
2025-08-28 14:36:04,395 - root - INFO - Iniciando bucle principal de la aplicación...
2025-08-28 18:08:02,209 - matplotlib - DEBUG - matplotlib data path: C:\Users\USER\AppData\Local\Packages\PythonSoftwareFoundation.Python.3.11_qbz5n2kfra8p0\LocalCache\local-packages\Python311\site-packages\matplotlib\mpl-data
2025-08-28 18:08:02,231 - matplotlib - DEBUG - CONFIGDIR=C:\Users\USER\.matplotlib
2025-08-28 18:08:02,234 - matplotlib - DEBUG - interactive is False
2025-08-28 18:08:02,235 - matplotlib - DEBUG - platform is win32
2025-08-28 18:08:02,260 - root - INFO - Matplotlib backend configurado correctamente
2025-08-28 18:08:02,331 - root - INFO - CustomTkinter importado correctamente
2025-08-28 18:08:02,876 - matplotlib - DEBUG - CACHEDIR=C:\Users\USER\.matplotlib
2025-08-28 18:08:02,881 - matplotlib.font_manager - DEBUG - Using fontManager instance from C:\Users\USER\.matplotlib\fontlist-v390.json
2025-08-28 18:08:03,196 - root - INFO - Módulo gui.app importado correctamente
2025-08-28 18:08:03,197 - root - INFO - Configuración de CustomTkinter establecida
2025-08-28 18:08:03,296 - root - INFO - Ventana principal creada
2025-08-28 18:08:03,873 - root - INFO - GenealogyApp inicializada correctamente
2025-08-28 18:08:03,873 - root - INFO - Iniciando bucle principal de la aplicación...
2025-08-28 18:17:51,044 - matplotlib - DEBUG - matplotlib data path: C:\Users\USER\AppData\Local\Packages\PythonSoftwareFoundation.Python.3.11_qbz5n2kfra8p0\LocalCache\local-packages\Python311\site-packages\matplotlib\mpl-data
2025-08-28 18:17:51,053 - matplotlib - DEBUG - CONFIGDIR=C:\Users\USER\.matplotlib
2025-08-28 18:17:51,055 - matplotlib - DEBUG - interactive is False
2025-08-28 18:17:51,055 - matplotlib - DEBUG - platform is win32
2025-08-28 18:17:51,071 - root - INFO - Matplotlib backend configurado correctamente
2025-08-28 18:17:51,186 - root - INFO - CustomTkinter importado correctamente
2025-08-28 18:17:51,425 - matplotlib - DEBUG - CACHEDIR=C:\Users\USER\.matplotlib
2025-08-28 18:17:51,427 - matplotlib.font_manager - DEBUG - Using fontManager instance from C:\Users\USER\.matplotlib\fontlist-v390.json
2025-08-28 18:17:51,611 - root - INFO - Módulo gui.app importado correctamente
2025-08-28 18:17:51,611 - root - INFO - Configuración de CustomTkinter establecida
2025-08-28 18:17:51,711 - root - INFO - Ventana principal creada
2025-08-28 18:17:52,272 - root - INFO - GenealogyApp inicializada correctamente
2025-08-28 18:17:52,273 - root - INFO - Iniciando bucle principal de la aplicación...
2025-08-28 18:30:21,975 - matplotlib - DEBUG - matplotlib data path: C:\Users\USER\AppData\Local\Packages\PythonSoftwareFoundation.Python.3.11_qbz5n2kfra8p0\LocalCache\local-packages\Python311\site-packages\matplotlib\mpl-data
2025-08-28 18:30:21,986 - matplotlib - DEBUG - CONFIGDIR=C:\Users\USER\.matplotlib
2025-08-28 18:30:21,987 - matplotlib - DEBUG - interactive is False
2025-08-28 18:30:21,987 - matplotlib - DEBUG - platform is win32
2025-08-28 18:30:22,003 - root - INFO - Matplotlib backend configurado correctamente
2025-08-28 18:30:22,132 - root - INFO - CustomTkinter importado correctamente
2025-08-28 18:30:22,475 - matplotlib - DEBUG - CACHEDIR=C:\Users\USER\.matplotlib
2025-08-28 18:30:22,478 - matplotlib.font_manager - DEBUG - Using fontManager instance from C:\Users\USER\.matplotlib\fontlist-v390.json
2025-08-28 18:30:22,687 - root - INFO - Módulo gui.app importado correctamente
2025-08-28 18:30:22,688 - root - INFO - Configuración de CustomTkinter establecida
2025-08-28 18:30:22,796 - root - INFO - Ventana principal creada
2025-08-28 18:30:23,329 - gui.simulation_panel - INFO - UI del panel de simulación configurada correctamente
2025-08-28 18:30:23,367 - root - INFO - GenealogyApp inicializada correctamente
2025-08-28 18:30:23,368 - root - INFO - Iniciando bucle principal de la aplicación...
2025-08-28 18:30:59,937 - gui.simulation_panel - ERROR - Error importando ejemplo: 'GedcomParser' object has no attribute 'parse_gedcom_file'
Traceback (most recent call last):
  File "C:\Users\USER\OneDrive\Escritorio\ArbolGenealogico\gui\simulation_panel.py", line 337, in importar_ejemplo
    ejemplo_family = parser.parse_gedcom_file(ejemplo_path)
                     ^^^^^^^^^^^^^^^^^^^^^^^^
AttributeError: 'GedcomParser' object has no attribute 'parse_gedcom_file'
2025-08-28 18:45:34,201 - matplotlib - DEBUG - matplotlib data path: C:\Users\USER\AppData\Local\Packages\PythonSoftwareFoundation.Python.3.11_qbz5n2kfra8p0\LocalCache\local-packages\Python311\site-packages\matplotlib\mpl-data
2025-08-28 18:45:34,211 - matplotlib - DEBUG - CONFIGDIR=C:\Users\USER\.matplotlib
2025-08-28 18:45:34,212 - matplotlib - DEBUG - interactive is False
2025-08-28 18:45:34,214 - matplotlib - DEBUG - platform is win32
2025-08-28 18:45:34,226 - root - INFO - Matplotlib backend configurado correctamente
2025-08-28 18:45:34,303 - root - INFO - CustomTkinter importado correctamente
2025-08-28 18:45:34,523 - matplotlib - DEBUG - CACHEDIR=C:\Users\USER\.matplotlib
2025-08-28 18:45:34,523 - matplotlib.font_manager - DEBUG - Using fontManager instance from C:\Users\USER\.matplotlib\fontlist-v390.json
2025-08-28 18:45:34,687 - root - INFO - Módulo gui.app importado correctamente
2025-08-28 18:45:34,687 - root - INFO - Configuración de CustomTkinter establecida
2025-08-28 18:45:34,770 - root - INFO - Ventana principal creada
2025-08-28 18:45:35,248 - gui.simulation_panel - INFO - UI del panel de simulación configurada correctamente
2025-08-28 18:45:35,298 - root - INFO - GenealogyApp inicializada correctamente
2025-08-28 18:45:35,298 - root - INFO - Iniciando bucle principal de la aplicación...
2025-08-28 18:53:19,094 - gui.simulation_panel - ERROR - Error importando ejemplo: 'GedcomParser' object has no attribute 'parse_gedcom_file'
Traceback (most recent call last):
  File "C:\Users\USER\OneDrive\Escritorio\ArbolGenealogico\gui\simulation_panel.py", line 337, in importar_ejemplo
    )
      
AttributeError: 'GedcomParser' object has no attribute 'parse_gedcom_file'
2025-08-28 18:53:51,117 - gui.simulation_panel - ERROR - Error importando ejemplo: 'GedcomParser' object has no attribute 'parse_gedcom_file'
Traceback (most recent call last):
  File "C:\Users\USER\OneDrive\Escritorio\ArbolGenealogico\gui\simulation_panel.py", line 337, in importar_ejemplo
    )
      
AttributeError: 'GedcomParser' object has no attribute 'parse_gedcom_file'
2025-08-28 18:57:10,127 - matplotlib - DEBUG - matplotlib data path: C:\Users\USER\AppData\Local\Packages\PythonSoftwareFoundation.Python.3.11_qbz5n2kfra8p0\LocalCache\local-packages\Python311\site-packages\matplotlib\mpl-data
2025-08-28 18:57:10,136 - matplotlib - DEBUG - CONFIGDIR=C:\Users\USER\.matplotlib
2025-08-28 18:57:10,137 - matplotlib - DEBUG - interactive is False
2025-08-28 18:57:10,137 - matplotlib - DEBUG - platform is win32
2025-08-28 18:57:10,149 - root - INFO - Matplotlib backend configurado correctamente
2025-08-28 18:57:10,236 - root - INFO - CustomTkinter importado correctamente
2025-08-28 18:57:10,471 - matplotlib - DEBUG - CACHEDIR=C:\Users\USER\.matplotlib
2025-08-28 18:57:10,472 - matplotlib.font_manager - DEBUG - Using fontManager instance from C:\Users\USER\.matplotlib\fontlist-v390.json
2025-08-28 18:57:10,639 - root - INFO - Módulo gui.app importado correctamente
2025-08-28 18:57:10,639 - root - INFO - Configuración de CustomTkinter establecida
2025-08-28 18:57:10,728 - root - INFO - Ventana principal creada
2025-08-28 18:57:11,132 - gui.simulation_panel - INFO - UI del panel de simulación configurada correctamente
2025-08-28 18:57:11,179 - root - INFO - GenealogyApp inicializada correctamente
2025-08-28 18:57:11,179 - root - INFO - Iniciando bucle principal de la aplicación...
2025-08-28 19:16:41,338 - matplotlib - DEBUG - matplotlib data path: C:\Users\USER\AppData\Local\Packages\PythonSoftwareFoundation.Python.3.11_qbz5n2kfra8p0\LocalCache\local-packages\Python311\site-packages\matplotlib\mpl-data
2025-08-28 19:16:41,358 - matplotlib - DEBUG - CONFIGDIR=C:\Users\USER\.matplotlib
2025-08-28 19:16:41,361 - matplotlib - DEBUG - interactive is False
2025-08-28 19:16:41,362 - matplotlib - DEBUG - platform is win32
2025-08-28 19:16:41,383 - root - INFO - Matplotlib backend configurado correctamente
2025-08-28 19:16:41,450 - root - INFO - CustomTkinter importado correctamente
2025-08-28 19:16:41,739 - matplotlib - DEBUG - CACHEDIR=C:\Users\USER\.matplotlib
2025-08-28 19:16:41,742 - matplotlib.font_manager - DEBUG - Using fontManager instance from C:\Users\USER\.matplotlib\fontlist-v390.json
2025-08-28 19:16:42,067 - root - INFO - Módulo gui.app importado correctamente
2025-08-28 19:16:42,068 - root - INFO - Configuración de CustomTkinter establecida
2025-08-28 19:16:42,178 - root - INFO - Ventana principal creada
2025-08-28 19:16:42,570 - gui.simulation_panel - INFO - UI del panel de simulación configurada correctamente
2025-08-28 19:16:42,644 - root - INFO - GenealogyApp inicializada correctamente
2025-08-28 19:16:42,644 - root - INFO - Iniciando bucle principal de la aplicación...
2025-08-28 19:16:59,937 - asyncio - INFO - Sofia Elena formó pareja con Miguel (persona externa)
2025-08-28 19:16:59,938 - asyncio - INFO - Nueva persona generada: Miguel Carballo, edad: 35
2025-08-28 19:16:59,940 - asyncio - INFO - Intereses comunes: ['Videojuegos', 'Libros']
2025-08-28 19:17:05,247 - asyncio - INFO - Luis Carlos formó pareja con Elena (persona externa)
2025-08-28 19:17:05,250 - asyncio - INFO - Nueva persona generada: Elena Esquivel, edad: 43
2025-08-28 19:17:05,262 - asyncio - INFO - Intereses comunes: ['Economía', 'Videojuegos']
2025-08-28 19:25:55,484 - matplotlib - DEBUG - matplotlib data path: C:\Users\USER\AppData\Local\Packages\PythonSoftwareFoundation.Python.3.11_qbz5n2kfra8p0\LocalCache\local-packages\Python311\site-packages\matplotlib\mpl-data
2025-08-28 19:25:55,492 - matplotlib - DEBUG - CONFIGDIR=C:\Users\USER\.matplotlib
2025-08-28 19:25:55,494 - matplotlib - DEBUG - interactive is False
2025-08-28 19:25:55,494 - matplotlib - DEBUG - platform is win32
2025-08-28 19:25:55,506 - root - INFO - Matplotlib backend configurado correctamente
2025-08-28 19:25:55,588 - root - INFO - CustomTkinter importado correctamente
2025-08-28 19:25:55,779 - matplotlib - DEBUG - CACHEDIR=C:\Users\USER\.matplotlib
2025-08-28 19:25:55,781 - matplotlib.font_manager - DEBUG - Using fontManager instance from C:\Users\USER\.matplotlib\fontlist-v390.json
2025-08-28 19:25:55,935 - root - INFO - Módulo gui.app importado correctamente
2025-08-28 19:25:55,937 - root - INFO - Configuración de CustomTkinter establecida
2025-08-28 19:25:56,017 - root - INFO - Ventana principal creada
2025-08-28 19:25:56,477 - gui.simulation_panel - INFO - UI del panel de simulación configurada correctamente
2025-08-28 19:25:56,527 - root - INFO - GenealogyApp inicializada correctamente
2025-08-28 19:25:56,527 - root - INFO - Iniciando bucle principal de la aplicación...
2025-08-28 19:26:34,040 - asyncio - INFO - Luis Carlos formó pareja con Patricia (persona externa)
2025-08-28 19:26:34,040 - asyncio - INFO - Nueva persona generada: Patricia Aguilar, edad: 36
2025-08-28 19:26:34,042 - asyncio - INFO - Intereses comunes: ['Comunidad', 'Series']
2025-08-28 19:26:35,087 - asyncio - INFO - Sofia Elena formó pareja con José (persona externa)
2025-08-28 19:26:35,087 - asyncio - INFO - Nueva persona generada: José Castro, edad: 35
2025-08-28 19:26:35,087 - asyncio - INFO - Intereses comunes: ['Eventos sociales', 'Filosofía']
2025-08-28 19:26:59,651 - asyncio - INFO - Patricia formó pareja con Diego (persona externa)
2025-08-28 19:26:59,652 - asyncio - INFO - Nueva persona generada: Diego Esquivel, edad: 22
2025-08-28 19:26:59,652 - asyncio - INFO - Intereses comunes: ['Juegos', 'Cuentos']
2025-08-28 19:27:04,734 - asyncio - INFO - Ana formó pareja con Oscar (persona externa)
2025-08-28 19:27:04,734 - asyncio - INFO - Nueva persona generada: Oscar Picado, edad: 19
2025-08-28 19:27:04,735 - asyncio - INFO - Intereses comunes: ['Música', 'Cuentos']
2025-08-28 19:27:09,604 - asyncio - INFO - Mario formó pareja con Verónica (persona externa)
2025-08-28 19:27:09,605 - asyncio - INFO - Nueva persona generada: Verónica Chaves, edad: 24
2025-08-28 19:27:09,605 - asyncio - INFO - Intereses comunes: ['Juegos', 'Dibujo']
2025-08-28 19:27:13,160 - asyncio - INFO - Luis formó pareja con Elena (persona externa)
2025-08-28 19:27:13,160 - asyncio - INFO - Nueva persona generada: Elena Salas, edad: 35
2025-08-28 19:27:13,160 - asyncio - INFO - Intereses comunes: ['Cuentos', 'Dibujo']
2025-08-28 19:27:30,027 - asyncio - INFO - Ricardo formó pareja con Paula (persona externa)
2025-08-28 19:27:30,027 - asyncio - INFO - Nueva persona generada: Paula Rojas, edad: 21
2025-08-28 19:27:30,027 - asyncio - INFO - Intereses comunes: ['Naturaleza', 'Juegos']
2025-08-28 19:27:33,389 - asyncio - INFO - Luis formó pareja con Carmen (persona externa)
2025-08-28 19:27:33,389 - asyncio - INFO - Nueva persona generada: Carmen Araya, edad: 28
2025-08-28 19:27:33,389 - asyncio - INFO - Intereses comunes: ['Cuentos', 'Música']
2025-08-28 19:27:33,389 - asyncio - INFO - Oscar formó pareja con Patricia (persona externa)
2025-08-28 19:27:33,390 - asyncio - INFO - Nueva persona generada: Patricia Cordero, edad: 21
2025-08-28 19:27:33,390 - asyncio - INFO - Intereses comunes: ['Cuentos', 'Juegos']
2025-08-28 19:27:35,687 - asyncio - INFO - Mónica formó pareja con Alberto (persona externa)
2025-08-28 19:27:35,687 - asyncio - INFO - Nueva persona generada: Alberto Solano, edad: 18
2025-08-28 19:27:35,687 - asyncio - INFO - Intereses comunes: ['Música', 'Juegos']
2025-08-28 19:27:42,770 - asyncio - INFO - Daniela formó pareja con Miguel (persona externa)
2025-08-28 19:27:42,771 - asyncio - INFO - Nueva persona generada: Miguel Trejos, edad: 18
2025-08-28 19:27:42,772 - asyncio - INFO - Intereses comunes: ['Naturaleza', 'Música']
2025-08-28 19:27:46,159 - asyncio - INFO - Paula formó pareja con Carlos (persona externa)
2025-08-28 19:27:46,159 - asyncio - INFO - Nueva persona generada: Carlos Herrera, edad: 28
2025-08-28 19:27:46,160 - asyncio - INFO - Intereses comunes: ['Naturaleza', 'Dibujo']
2025-08-28 19:27:48,605 - asyncio - INFO - Sofía formó pareja con Alberto (persona externa)
2025-08-28 19:27:48,605 - asyncio - INFO - Nueva persona generada: Alberto Mora, edad: 40
2025-08-28 19:27:48,606 - asyncio - INFO - Intereses comunes: ['Naturaleza', 'Cuentos']
2025-08-28 19:27:49,854 - asyncio - INFO - Andrés formó pareja con Claudia (persona externa)
2025-08-28 19:27:49,854 - asyncio - INFO - Nueva persona generada: Claudia Segura, edad: 39
2025-08-28 19:27:49,855 - asyncio - INFO - Intereses comunes: ['Dibujo', 'Naturaleza']
2025-08-28 19:27:51,054 - asyncio - INFO - Miguel formó pareja con Carolina (persona externa)
2025-08-28 19:27:51,055 - asyncio - INFO - Nueva persona generada: Carolina Villalobos, edad: 31
2025-08-28 19:27:51,057 - asyncio - INFO - Intereses comunes: ['Juegos', 'Dibujo']
2025-08-28 19:27:56,109 - asyncio - INFO - Claudia formó pareja con Ricardo (persona externa)
2025-08-28 19:27:56,110 - asyncio - INFO - Nueva persona generada: Ricardo Ramírez, edad: 23
2025-08-28 19:27:56,110 - asyncio - INFO - Intereses comunes: ['Naturaleza', 'Cuentos']
2025-08-28 19:27:56,111 - asyncio - INFO - Juan formó pareja con Sofía (persona externa)
2025-08-28 19:27:56,111 - asyncio - INFO - Nueva persona generada: Sofía Vega, edad: 30
2025-08-28 19:27:56,111 - asyncio - INFO - Intereses comunes: ['Juegos', 'Dibujo']
2025-08-28 19:28:04,107 - asyncio - INFO - Andrés formó pareja con Laura (persona externa)
2025-08-28 19:28:04,107 - asyncio - INFO - Nueva persona generada: Laura Quesada, edad: 23
2025-08-28 19:28:04,107 - asyncio - INFO - Intereses comunes: ['Cuentos', 'Dibujo']
2025-08-28 19:28:06,791 - asyncio - INFO - Raúl formó pareja con Gabriela (persona externa)
2025-08-28 19:28:06,792 - asyncio - INFO - Nueva persona generada: Gabriela Mendez, edad: 18
2025-08-28 19:28:06,793 - asyncio - INFO - Intereses comunes: ['Dibujo', 'Naturaleza']
2025-08-28 19:28:06,793 - asyncio - INFO - Carlos formó pareja con Mónica (persona externa)
2025-08-28 19:28:06,794 - asyncio - INFO - Nueva persona generada: Mónica Monge, edad: 18
2025-08-28 19:28:06,794 - asyncio - INFO - Intereses comunes: ['Dibujo', 'Naturaleza']
2025-08-28 19:28:08,122 - asyncio - INFO - Carmen formó pareja con Diego (persona externa)
2025-08-28 19:28:08,123 - asyncio - INFO - Nueva persona generada: Diego Carballo, edad: 19
2025-08-28 19:28:08,124 - asyncio - INFO - Intereses comunes: ['Música', 'Juegos']
2025-08-28 19:28:10,466 - asyncio - INFO - Sofía formó pareja con Víctor (persona externa)
2025-08-28 19:28:10,466 - asyncio - INFO - Nueva persona generada: Víctor Salas, edad: 21
2025-08-28 19:28:10,467 - asyncio - INFO - Intereses comunes: ['Dibujo', 'Juegos']
2025-08-28 19:28:11,795 - asyncio - INFO - Mónica formó pareja con Miguel (persona externa)
2025-08-28 19:28:11,795 - asyncio - INFO - Nueva persona generada: Miguel Rojas, edad: 38
2025-08-28 19:28:11,795 - asyncio - INFO - Intereses comunes: ['Naturaleza', 'Juegos']
2025-08-28 19:28:11,796 - asyncio - INFO - Diego formó pareja con Claudia (persona externa)
2025-08-28 19:28:11,796 - asyncio - INFO - Nueva persona generada: Claudia Monge, edad: 37
2025-08-28 19:28:11,797 - asyncio - INFO - Intereses comunes: ['Naturaleza', 'Arte']
2025-08-28 19:28:20,350 - asyncio - INFO - Raúl formó pareja con Claudia (persona externa)
2025-08-28 19:28:20,351 - asyncio - INFO - Nueva persona generada: Claudia Trejos, edad: 29
2025-08-28 19:28:20,352 - asyncio - INFO - Intereses comunes: ['Naturaleza', 'Cuentos']
2025-08-28 19:28:20,352 - asyncio - INFO - Luis formó pareja con Isabel (persona externa)
2025-08-28 19:28:20,352 - asyncio - INFO - Nueva persona generada: Isabel Segura, edad: 26
2025-08-28 19:28:20,353 - asyncio - INFO - Intereses comunes: ['Música', 'Dibujo']
2025-08-28 19:32:27,474 - matplotlib - DEBUG - matplotlib data path: C:\Users\USER\AppData\Local\Packages\PythonSoftwareFoundation.Python.3.11_qbz5n2kfra8p0\LocalCache\local-packages\Python311\site-packages\matplotlib\mpl-data
2025-08-28 19:32:27,475 - matplotlib - DEBUG - matplotlib data path: C:\Users\USER\AppData\Local\Packages\PythonSoftwareFoundation.Python.3.11_qbz5n2kfra8p0\LocalCache\local-packages\Python311\site-packages\matplotlib\mpl-data
2025-08-28 19:32:27,604 - matplotlib - DEBUG - CONFIGDIR=C:\Users\USER\.matplotlib
2025-08-28 19:32:27,605 - matplotlib - DEBUG - CONFIGDIR=C:\Users\USER\.matplotlib
2025-08-28 19:32:27,608 - matplotlib - DEBUG - interactive is False
2025-08-28 19:32:27,609 - matplotlib - DEBUG - platform is win32
2025-08-28 19:32:27,609 - matplotlib - DEBUG - interactive is False
2025-08-28 19:32:27,609 - matplotlib - DEBUG - platform is win32
2025-08-28 19:32:27,777 - root - INFO - Matplotlib backend configurado correctamente
2025-08-28 19:32:27,777 - root - INFO - Matplotlib backend configurado correctamente
2025-08-28 19:32:29,193 - root - INFO - CustomTkinter importado correctamente
2025-08-28 19:32:29,193 - root - INFO - CustomTkinter importado correctamente
2025-08-28 19:32:36,474 - matplotlib - DEBUG - CACHEDIR=C:\Users\USER\.matplotlib
2025-08-28 19:32:36,475 - matplotlib - DEBUG - CACHEDIR=C:\Users\USER\.matplotlib
2025-08-28 19:32:36,498 - matplotlib.font_manager - DEBUG - Using fontManager instance from C:\Users\USER\.matplotlib\fontlist-v390.json
2025-08-28 19:32:36,503 - matplotlib.font_manager - DEBUG - Using fontManager instance from C:\Users\USER\.matplotlib\fontlist-v390.json
2025-08-28 19:32:38,921 - root - INFO - Módulo gui.app importado correctamente
2025-08-28 19:32:38,922 - root - INFO - Configuración de CustomTkinter establecida
2025-08-28 19:32:38,922 - root - INFO - Configuración de CustomTkinter establecida
2025-08-28 19:32:40,117 - root - INFO - Ventana principal creada
2025-08-28 19:32:40,131 - root - INFO - Ventana principal creada
2025-08-28 19:32:41,880 - gui.simulation_panel - INFO - UI del panel de simulación configurada correctamente
2025-08-28 19:32:41,881 - gui.simulation_panel - INFO - UI del panel de simulación configurada correctamente
2025-08-28 19:32:41,959 - root - INFO - GenealogyApp inicializada correctamente
2025-08-28 19:32:41,959 - root - INFO - GenealogyApp inicializada correctamente
2025-08-28 19:32:41,960 - root - INFO - Iniciando bucle principal de la aplicación...
2025-08-28 19:32:41,960 - root - INFO - Iniciando bucle principal de la aplicación...
2025-08-28 19:40:32,540 - matplotlib - DEBUG - matplotlib data path: C:\Users\USER\AppData\Local\Packages\PythonSoftwareFoundation.Python.3.11_qbz5n2kfra8p0\LocalCache\local-packages\Python311\site-packages\matplotlib\mpl-data
2025-08-28 19:40:32,565 - matplotlib - DEBUG - CONFIGDIR=C:\Users\USER\.matplotlib
2025-08-28 19:40:32,569 - matplotlib - DEBUG - interactive is False
2025-08-28 19:40:32,570 - matplotlib - DEBUG - platform is win32
2025-08-28 19:40:32,601 - root - INFO - Matplotlib backend configurado correctamente
2025-08-28 19:40:32,695 - root - INFO - CustomTkinter importado correctamente
2025-08-28 19:40:32,979 - matplotlib - DEBUG - CACHEDIR=C:\Users\USER\.matplotlib
2025-08-28 19:40:32,982 - matplotlib.font_manager - DEBUG - Using fontManager instance from C:\Users\USER\.matplotlib\fontlist-v390.json
2025-08-28 19:40:33,345 - root - INFO - Módulo gui.app importado correctamente
2025-08-28 19:40:33,347 - root - INFO - Configuración de CustomTkinter establecida
2025-08-28 19:40:33,454 - root - INFO - Ventana principal creada
2025-08-28 19:40:33,929 - gui.simulation_panel - INFO - UI del panel de simulación configurada correctamente
2025-08-28 19:40:33,981 - root - INFO - GenealogyApp inicializada correctamente
2025-08-28 19:40:33,982 - root - INFO - Iniciando bucle principal de la aplicación...
2025-08-28 19:40:47,444 - asyncio - INFO - Sofia Elena formó pareja con Andrés (persona externa)
2025-08-28 19:40:47,445 - asyncio - INFO - Nueva persona generada: Andrés Picado, edad: 21
2025-08-28 19:40:47,445 - asyncio - INFO - Intereses comunes: ['Conciertos', 'Senderismo']
2025-08-28 19:41:46,823 - asyncio - INFO - Luis Carlos formó pareja con Claudia (persona externa)
2025-08-28 19:41:46,824 - asyncio - INFO - Nueva persona generada: Claudia Chaves, edad: 54
2025-08-28 19:41:46,825 - asyncio - INFO - Intereses comunes: ['Vinos', 'Café']
2025-08-28 19:42:48,663 - gui.simulation_panel - INFO - Árbol de simulación limpiado exitosamente
2025-08-28 19:43:08,646 - asyncio - INFO - Luis Carlos formó pareja con Ana (persona externa)
2025-08-28 19:43:08,648 - asyncio - INFO - Nueva persona generada: Ana Trejos, edad: 24
2025-08-28 19:43:08,648 - asyncio - INFO - Intereses comunes: ['Pintura', 'Terapias alternativas']
2025-08-28 19:43:08,649 - asyncio - INFO - Sofia Elena formó pareja con Carlos (persona externa)
2025-08-28 19:43:08,649 - asyncio - INFO - Nueva persona generada: Carlos Aguilar, edad: 24
2025-08-28 19:43:08,650 - asyncio - INFO - Intereses comunes: ['Mindfulness', 'Pintura']
2025-08-28 19:44:26,846 - gui.simulation_panel - INFO - Árbol de simulación limpiado exitosamente
2025-08-28 19:44:37,152 - asyncio - INFO - Sofia Elena formó pareja con Ricardo (persona externa)
2025-08-28 19:44:37,152 - asyncio - INFO - Nueva persona generada: Ricardo Vega, edad: 27
2025-08-28 19:44:37,152 - asyncio - INFO - Intereses comunes: ['Bailar', 'Conciertos']
2025-08-28 19:44:42,153 - asyncio - INFO - Luis Carlos formó pareja con Verónica (persona externa)
2025-08-28 19:44:42,154 - asyncio - INFO - Nueva persona generada: Verónica Mora, edad: 26
2025-08-28 19:44:42,156 - asyncio - INFO - Intereses comunes: ['Nutrición', 'Libros']
2025-08-28 19:45:35,460 - gui.simulation_panel - INFO - Árbol de simulación limpiado exitosamente
2025-08-28 19:49:16,597 - matplotlib - DEBUG - matplotlib data path: C:\Users\USER\AppData\Local\Packages\PythonSoftwareFoundation.Python.3.11_qbz5n2kfra8p0\LocalCache\local-packages\Python311\site-packages\matplotlib\mpl-data
2025-08-28 19:49:16,611 - matplotlib - DEBUG - CONFIGDIR=C:\Users\USER\.matplotlib
2025-08-28 19:49:16,612 - matplotlib - DEBUG - interactive is False
2025-08-28 19:49:16,612 - matplotlib - DEBUG - platform is win32
2025-08-28 19:49:16,628 - root - INFO - Matplotlib backend configurado correctamente
2025-08-28 19:49:16,740 - root - INFO - CustomTkinter importado correctamente
2025-08-28 19:49:17,058 - matplotlib - DEBUG - CACHEDIR=C:\Users\USER\.matplotlib
2025-08-28 19:49:17,060 - matplotlib.font_manager - DEBUG - Using fontManager instance from C:\Users\USER\.matplotlib\fontlist-v390.json
2025-08-28 19:49:17,300 - root - INFO - Módulo gui.app importado correctamente
2025-08-28 19:49:17,302 - root - INFO - Configuración de CustomTkinter establecida
2025-08-28 19:49:17,402 - root - INFO - Ventana principal creada
2025-08-28 19:49:18,047 - gui.simulation_panel - INFO - UI del panel de simulación configurada correctamente
2025-08-28 19:49:18,102 - root - INFO - GenealogyApp inicializada correctamente
2025-08-28 19:49:18,102 - root - INFO - Iniciando bucle principal de la aplicación...
2025-08-28 20:03:29,926 - matplotlib - DEBUG - matplotlib data path: C:\Users\USER\AppData\Local\Packages\PythonSoftwareFoundation.Python.3.11_qbz5n2kfra8p0\LocalCache\local-packages\Python311\site-packages\matplotlib\mpl-data
2025-08-28 20:03:29,938 - matplotlib - DEBUG - CONFIGDIR=C:\Users\USER\.matplotlib
2025-08-28 20:03:29,940 - matplotlib - DEBUG - interactive is False
2025-08-28 20:03:29,941 - matplotlib - DEBUG - platform is win32
2025-08-28 20:03:29,954 - root - INFO - Matplotlib backend configurado correctamente
2025-08-28 20:03:30,051 - root - INFO - CustomTkinter importado correctamente
2025-08-28 20:03:30,357 - matplotlib - DEBUG - CACHEDIR=C:\Users\USER\.matplotlib
2025-08-28 20:03:30,359 - matplotlib.font_manager - DEBUG - Using fontManager instance from C:\Users\USER\.matplotlib\fontlist-v390.json
2025-08-28 20:03:30,557 - root - INFO - Módulo gui.app importado correctamente
2025-08-28 20:03:30,559 - root - INFO - Configuración de CustomTkinter establecida
2025-08-28 20:03:30,663 - root - INFO - Ventana principal creada
2025-08-28 20:03:31,399 - gui.simulation_panel - INFO - UI del panel de simulación configurada correctamente
2025-08-28 20:03:31,468 - root - INFO - GenealogyApp inicializada correctamente
2025-08-28 20:03:31,468 - root - INFO - Iniciando bucle principal de la aplicación...
2025-08-28 20:07:48,191 - matplotlib - DEBUG - matplotlib data path: C:\Users\USER\AppData\Local\Packages\PythonSoftwareFoundation.Python.3.11_qbz5n2kfra8p0\LocalCache\local-packages\Python311\site-packages\matplotlib\mpl-data
2025-08-28 20:07:48,215 - matplotlib - DEBUG - CONFIGDIR=C:\Users\USER\.matplotlib
2025-08-28 20:07:48,219 - matplotlib - DEBUG - interactive is False
2025-08-28 20:07:48,219 - matplotlib - DEBUG - platform is win32
2025-08-28 20:07:48,251 - root - INFO - Matplotlib backend configurado correctamente
2025-08-28 20:07:48,431 - root - INFO - CustomTkinter importado correctamente
2025-08-28 20:07:48,789 - matplotlib - DEBUG - CACHEDIR=C:\Users\USER\.matplotlib
2025-08-28 20:07:48,792 - matplotlib.font_manager - DEBUG - Using fontManager instance from C:\Users\USER\.matplotlib\fontlist-v390.json
2025-08-28 20:07:49,154 - root - INFO - Módulo gui.app importado correctamente
2025-08-28 20:07:49,155 - root - INFO - Configuración de CustomTkinter establecida
2025-08-28 20:07:49,254 - root - INFO - Ventana principal creada
2025-08-28 20:07:49,816 - gui.simulation_panel - INFO - UI del panel de simulación configurada correctamente
2025-08-28 20:07:49,877 - root - INFO - GenealogyApp inicializada correctamente
2025-08-28 20:07:49,877 - root - INFO - Iniciando bucle principal de la aplicación...
2025-08-28 20:08:22,336 - asyncio - INFO - Luis Carlos formó pareja con Isabel (persona externa)
2025-08-28 20:08:22,337 - asyncio - INFO - Nueva persona generada: Isabel Vega, edad: 32
2025-08-28 20:08:22,337 - asyncio - INFO - Intereses comunes: ['Series', 'Electrónica']
2025-08-28 20:09:46,273 - gui.simulation_panel - INFO - Árbol de simulación limpiado exitosamente
2025-08-28 20:10:48,657 - asyncio - INFO - Luis Carlos formó pareja con Verónica (persona externa)
2025-08-28 20:10:48,659 - asyncio - INFO - Nueva persona generada: Verónica Cordero, edad: 28
2025-08-28 20:10:48,659 - asyncio - INFO - Intereses comunes: ['Libros', 'Festivales']
